Workbook
Name Actual: #REF!
Name ARAging: #REF!
Name ARAging_Health: #REF!
Name DaysToRenewal: #REF!
Name DaysToRenewalResults: #REF!
Name LastInteraction: #REF!
Name LastInteractionResult: #REF!
Name LastVisit: #REF!
Name LastVisitResult: #REF!
Name LCM_Incident_Rate: #REF!
Name LCM_Incident_RateWeight: #REF!
Name LCM_SLA: #REF!
Name LCM_SLA_Score: #REF!
Name MOC_ASA: #REF!
Name MOC_ASA_Result: #REF!
Name MOC_FCR: #REF!
Name MOC_FCR_Results: #REF!
Name MOC_IncidentRate: #REF!
Name MOC_IncidentRate_Results: #REF!
Name MRR: #REF!
Name MRRResults: #REF!
Name NPS_Actual: #REF!
Name NPS_Score: #REF!
Name OpenIssue: #REF!
Name OpenIssueResult: #REF!
Name QBR_Last: #REF!
Name QBR_Score: #REF!
Name Score: #REF!
Name Solutions: [1]!Table4[Solution]
Name Solutions: [1]!Table4[Solution]
Name Solutions: [1]!Table4[Solution]

Sheet Scorecard
U1: Date updated
U2: 46686

Sheet Overages
A1: MOC - Verifone | I1: MOC - non Verifone | P1: Combined MOC Tickets (used to calculate Overages)
A2: Month | B2: Tickets Opened | C2: Install base | D2: Actual Incident Rate (5% Contractual) | E2: Tickets Allowed | F2: Tickets Over | I2: Month | J2: Tickets Opened | K2: Install base | L2: Actual Incident Rate (5% Contractual) | M2: Tickets Allowed | N2: Tickets Over | P2: Allowed Tickets | Q2: Opened Tickets | R2: Tickets Over | S2: Overage
A3: Jan | B3: 871 | C3: 10081 | D3: =B3/C3 -> 0.086400159 | E3: =ROUND((C3*3%),0) -> 302 | F3: =B3-E3 -> 569 | I3: Jan | J3: 215 | K3: 7000 | L3: =J3/K3 -> 0.030714286 | M3: =ROUND(K3*0.03,0) -> 210 | N3: =J3-M3 -> 5
A4: Feb | B4: 663 | C4: 10081 | D4: =B4/C4 -> 0.065767285 | E4: =ROUND((C4*3%),0) -> 302 | F4: =B4-E4 -> 361 | I4: Feb | J4: 218 | K4: 7000 | L4: =J4/K4 -> 0.031142857 | M4: =ROUND(K4*0.03,0) -> 210 | N4: =J4-M4 -> 8
A5: Mar | B5: 718 | C5: 10174 | D5: =B5/C5 -> 0.070572046 | E5: =ROUND((C5*3%),0) -> 305 | F5: =B5-E5 -> 413 | I5: Mar | J5: 276 | K5: 7000 | L5: =J5/K5 -> 0.039428571 | M5: =ROUND(K5*0.03,0) -> 210 | N5: =J5-M5 -> 66
A6: Apr | B6: 696 | C6: 10142 | D6: =B6/C6 -> 0.068625518 | E6: =ROUND((C6*3%),0) -> 304 | F6: =B6-E6 -> 392 | I6: Apr | J6: 288 | K6: 7000 | L6: =J6/K6 -> 0.041142857 | M6: =ROUND(K6*0.03,0) -> 210 | N6: =J6-M6 -> 78
A7: May | B7: 772 | C7: 10428 | D7: =B7/C7 -> 0.074031454 | E7: =ROUND((C7*3%),0) -> 313 | F7: =B7-E7 -> 459 | I7: May | J7: 364 | K7: 7000 | L7: =J7/K7 -> 0.052 | M7: =ROUND(K7*0.03,0) -> 210 | N7: =J7-M7 -> 154
A8: June | B8: 852 | C8: 10575 | D8: =B8/C8 -> 0.080567376 | E8: =ROUND((C8*3%),0) -> 317 | F8: =B8-E8 -> 535 | I8: June | J8: 491 | K8: 7000 | L8: =J8/K8 -> 0.070142857 | M8: =ROUND(K8*0.03,0) -> 210 | N8: =J8-M8 -> 281
A9: Jul (old rate) | B9: 504 | C9: 10773 | D9: =B9/C9 -> 0.046783626 | E9: =ROUND((C9*3%),0) -> 323 | F9: =B9-E9 -> 181 | I9: Jul (old rate) | J9: 187 | K9: 7000 | L9: =J9/K9 -> 0.026714286 | M9: =ROUND(K9*0.03,0) -> 210 | N9: =J9-M9 -> -23
A10: Jul (new rate) | B10: 450 | C10: 10773 | D10: =B10/C10 -> 0.041771094 | E10: =ROUND((C10*5%),0) -> 539 | F10: =B10-E10 -> -89 | I10: Jul (new rate) | J10: 227 | K10: 12174 | L10: =J10/K10 -> 0.018646295 | M10: =ROUND(K10*0.05,0) -> 609 | N10: =J10-M10 -> -382
A11: Aug | B11: 696 | C11: 11086 | D11: =B11/C11 -> 0.062781887 | E11: =ROUND((C11*5%),0) -> 554 | F11: =B11-E11 -> 142 | I11: Aug | J11: 422 | K11: 12174 | L11: =J11/K11 -> 0.034664038 | M11: =ROUND(K11*0.05,0) -> 609 | N11: =J11-M11 -> -187 | P11: =E11+M11 -> 1163 | Q11: =B11+J11 -> 1118 | R11: =Q11-P11 -> -45 | S11: =IF(R11<0,"$0",(R11*39)) -> $0
A12: Sep | B12: 582 | C12: 11179 | D12: =B12/C12 -> 0.052061902 | E12: =ROUND((C12*5%),0) -> 559 | F12: =B12-E12 -> 23 | I12: Sep | J12: 488 | K12: 12174 | L12: =J12/K12 -> 0.040085428 | M12: =ROUND(K12*0.05,0) -> 609 | N12: =J12-M12 -> -121 | P12: =E12+M12 -> 1168 | Q12: =B12+J12 -> 1070 | R12: =Q12-P12 -> -98 | S12: =IF(R12<0,"$0",(R12*39)) -> $0
A13: Oct | B13: 591 | C13: 11304 | D13: =B13/C13 -> 0.052282378 | E13: =ROUND((C13*5%),0) -> 565 | F13: =B13-E13 -> 26 | I13: Oct | J13: 358 | K13: 12174 | L13: =J13/K13 -> 0.029406933 | M13: =ROUND(K13*0.05,0) -> 609 | N13: =J13-M13 -> -251 | P13: =E13+M13 -> 1174 | Q13: =B13+J13 -> 949 | R13: =Q13-P13 -> -225 | S13: =IF(R13<0,"$0",(R13*39)) -> $0
A14: Nov | B14: 591 | C14: 11343 | D14: =B14/C14 -> 0.052102618 | E14: =ROUND((C14*5%),0) -> 567 | F14: =B14-E14 -> 24 | I14: Nov | J14: 501 | K14: 12174 | L14: =J14/K14 -> 0.041153277 | M14: =ROUND(K14*0.05,0) -> 609 | N14: =J14-M14 -> -108 | P14: =E14+M14 -> 1176 | Q14: =B14+J14 -> 1092 | R14: =Q14-P14 -> -84 | S14: =IF(R14<0,"$0",(R14*39)) -> $0
A15: Dec | B15: 647 | C15: 11447 | D15: =B15/C15 -> 0.056521359 | E15: =ROUND((C15*5%),0) -> 572 | F15: =B15-E15 -> 75 | I15: Dec | J15: 314 | K15: 12202 | L15: =J15/K15 -> 0.025733486 | M15: =ROUND(K15*0.05,0) -> 610 | N15: =J15-M15 -> -296 | P15: =E15+M15 -> 1182 | Q15: =B15+J15 -> 961 | R15: =Q15-P15 -> -221 | S15: =IF(R15<0,"$0",(R15*39)) -> $0
A16: Jan | B16: 707 | C16: 11728 | D16: =B16/C16 -> 0.060283083 | E16: =ROUND((C16*5%),0) -> 586 | F16: =B16-E16 -> 121 | I16: Jan | J16: 276 | K16: 12202 | L16: =J16/K16 -> 0.022619243 | M16: =ROUND(K16*0.05,0) -> 610 | N16: =J16-M16 -> -334 | P16: =E16+M16 -> 1196 | Q16: =B16+J16 -> 983 | R16: =Q16-P16 -> -213 | S16: =IF(R16<0,"$0",(R16*39)) -> $0
A17: Feb | B17: 713 | C17: 11842 | D17: =B17/C17 -> 0.060209424 | E17: =ROUND((C17*5%),0) -> 592 | F17: =B17-E17 -> 121 | I17: Feb | J17: 226 | K17: 12202 | L17: =J17/K17 -> 0.018521554 | M17: =ROUND(K17*0.05,0) -> 610 | N17: =J17-M17 -> -384 | P17: =E17+M17 -> 1202 | Q17: =B17+J17 -> 939 | R17: =Q17-P17 -> -263 | S17: =IF(R17<0,"$0",(R17*39)) -> $0
A18: Mar | B18: 844 | C18: 12136 | D18: =B18/C18 -> 0.069545155 | E18: =ROUND((C18*5%),0) -> 607 | F18: =B18-E18 -> 237 | I18: Mar | J18: 156 | K18: 12202 | L18: =J18/K18 -> 0.012784789 | M18: =ROUND(K18*0.05,0) -> 610 | N18: =J18-M18 -> -454 | P18: =E18+M18 -> 1217 | Q18: =B18+J18 -> 1000 | R18: =Q18-P18 -> -217 | S18: =IF(R18<0,"$0",(R18*39)) -> $0
A19: Apr | B19: 824 | C19: 12306 | D19: =B19/C19 -> 0.066959207 | E19: =ROUND((C19*5%),0) -> 615 | F19: =B19-E19 -> 209 | I19: Apr | J19: 135 | K19: 12202 | L19: =J19/K19 -> 0.01106376 | M19: =ROUND(K19*0.05,0) -> 610 | N19: =J19-M19 -> -475 | P19: =E19+M19 -> 1225 | Q19: =B19+J19 -> 959 | R19: =Q19-P19 -> -266 | S19: =IF(R19<0,"$0",(R19*39)) -> $0
A20: May | B20: 736 | C20: 12601 | D20: =B20/C20 -> 0.058408063 | E20: =ROUND((C20*5%),0) -> 630 | F20: =B20-E20 -> 106 | I20: May | J20: 179 | K20: 12202 | L20: =J20/K20 -> 0.014669726 | M20: =ROUND(K20*0.05,0) -> 610 | N20: =J20-M20 -> -431 | P20: =E20+M20 -> 1240 | Q20: =B20+J20 -> 915 | R20: =Q20-P20 -> -325 | S20: =IF(R20<0,"$0",(R20*39)) -> $0
A21: June | B21: 955 | C21: 12740 | D21: =B21/C21 -> 0.074960754 | E21: =ROUND((C21*5%),0) -> 637 | F21: =B21-E21 -> 318 | I21: June | J21: 264 | K21: 13060 | L21: =J21/K21 -> 0.020214395 | M21: =ROUND(K21*0.05,0) -> 653 | N21: =J21-M21 -> -389 | P21: =E21+M21 -> 1290 | Q21: =B21+J21 -> 1219 | R21: =Q21-P21 -> -71 | S21: =IF(R21<0,"$0",(R21*39)) -> $0
A22: July | B22: 943 | C22: 12936 | D22: =B22/C22 -> 0.072897341 | E22: =ROUND((C22*5%),0) -> 647 | F22: =B22-E22 -> 296 | I22: July | J22: 582 | K22: 13060 | L22: =J22/K22 -> 0.044563553 | M22: =ROUND(K22*0.05,0) -> 653 | N22: =J22-M22 -> -71 | P22: =E22+M22 -> 1300 | Q22: =B22+J22 -> 1525 | R22: =Q22-P22 -> 225 | S22: =IF(R22<0,"$0",(R22*39)) -> 8775
... A28: Jan | B28: 855 | C28: 14247 | D28: =B28/C28 -> 0.060012634 | E28: =ROUND((C28*5%),0) -> 712 | F28: =B28-E28 -> 143 | I28: Jan | J28: 567 | K28: 14400 | L28: =J28/K28 -> 0.039375 | M28: =ROUND(K28*0.05,0) -> 720 | N28: =J28-M28 -> -153 | P28: =E28+M28 -> 1432 | Q28: =B28+J28 -> 1422 | R28: =Q28-P28 -> -10 | S28: =IF(R28<0,"$0",(R28*39)) -> $0
A29: Feb | B29: 883 | C29: 14579 | D29: =B29/C29 -> 0.060566568 | E29: =ROUND((C29*5%),0) -> 729 | F29: =B29-E29 -> 154 | I29: Feb | J29: 659 | K29: 14400 | L29: =J29/K29 -> 0.045763889 | M29: =ROUND(K29*0.05,0) -> 720 | N29: =J29-M29 -> -61 | P29: =E29+M29 -> 1449 | Q29: =B29+J29 -> 1542 | R29: 94 | S29: =IF(R29<0,"$0",(R29*39)) -> 3666
A30: Mar | B30: 872 | C30: 14831 | D30: =B30/C30 -> 0.058795766 | E30: =ROUND((C30*5%),0) -> 742 | F30: =B30-E30 -> 130 | I30: Mar | J30: 585 | K30: 14400 | L30: =J30/K30 -> 0.040625 | M30: =ROUND(K30*0.05,0) -> 720 | N30: =J30-M30 -> -135 | P30: =E30+M30 -> 1462 | Q30: =B30+J30 -> 1457 | R30: =Q30-P30 -> -5 | S30: =IF(R30<0,"$0",(R30*39)) -> $0
A31: Apr | B31: 974 | C31: 15033 | D31: =B31/C31 -> 0.064790794 | E31: =ROUND((C31*5%),0) -> 752 | F31: =B31-E31 -> 222 | I31: Apr | J31: 614 | K31: 14400 | L31: =J31/K31 -> 0.042638889 | M31: =ROUND(K31*0.05,0) -> 720 | N31: =J31-M31 -> -106 | P31: 1471 | Q31: =B31+J31 -> 1588 | R31: 117 | S31: =IF(R31<0,"$0",(R31*39)) -> 4563
A32: May | B32: 1013 | C32: 15194 | D32: =B32/C32 -> 0.066671054 | E32: =ROUND((C32*5%),0) -> 760 | F32: =B32-E32 -> 253 | I32: May | J32: 784 | K32: 14400 | L32: =J32/K32 -> 0.054444444 | M32: =ROUND(K32*0.05,0) -> 720 | N32: =J32-M32 -> 64 | P32: =E32+M32 -> 1480 | Q32: =B32+J32 -> 1797 | R32: =Q32-P32 -> 317 | S32: =IF(R32<0,"$0",(R32*39)) -> 12363
A33: Jun | B33: 1001 | C33: 15471 | D33: =B33/C33 -> 0.0647017 | E33: =ROUND((C33*5%),0) -> 774 | F33: =B33-E33 -> 227 | I33: Jun | J33: 831 | K33: 14400 | L33: =J33/K33 -> 0.057708333 | M33: =ROUND(K33*0.05,0) -> 720 | N33: =J33-M33 -> 111 | P33: =E33+M33 -> 1494 | Q33: =B33+J33 -> 1832 | R33: 339 | S33: =IF(R33<0,"$0",(R33*39)) -> 13221
A34: Jul | B34: 1263 | C34: 15926 | D34: =B34/C34 -> 0.079304282 | E34: =ROUND((C34*5%),0) -> 796 | F34: =B34-E34 -> 467 | I34: Jul | J34: 849 | K34: 14400 | L34: =J34/K34 -> 0.058958333 | M34: =ROUND(K34*0.05,0) -> 720 | N34: =J34-M34 -> 129 | P34: =E34+M34 -> 1516 | Q34: =B34+J34 -> 2112 | R34: =Q34-P34 -> 596 | S34: =IF(R34<0,"$0",(R34*39)) -> 23244
A35: Aug | B35: 1274 | C35: 16151 | D35: =B35/C35 -> 0.078880565 | E35: =ROUND((C35*5%),0) -> 808 | F35: =B35-E35 -> 466 | I35: Aug | J35: 707 | K35: 14400 | L35: =J35/K35 -> 0.049097222 | M35: =ROUND(K35*0.05,0) -> 720 | N35: =J35-M35 -> -13 | P35: =E35+M35 -> 1528 | Q35: =B35+J35 -> 1981 | R35: 454 | S35: =IF(R35<0,"$0",(R35*39)) -> 17706
A36: Sep | B36: 1139 | C36: 16354 | D36: =B36/C36 -> 0.06964657 | E36: =ROUND((C36*5%),0) -> 818 | F36: =B36-E36 -> 321 | I36: Sep | J36: 829 | K36: 14400 | L36: =J36/K36 -> 0.057569444 | M36: =ROUND(K36*0.05,0) -> 720 | N36: =J36-M36 -> 109 | P36: =E36+M36 -> 1538 | Q36: =B36+J36 -> 1968 | R36: =Q36-P36 -> 430 | S36: =IF(R36<0,"$0",(R36*39)) -> 16770
A37: Oct | B37: 855 | C37: 16354 | D37: =B37/C37 -> 0.052280788 | E37: =ROUND((C37*5%),0) -> 818 | F37: =B37-E37 -> 37 | I37: Oct | J37: 226 | K37: 14400 | L37: =J37/K37 -> 0.015694444 | M37: =ROUND(K37*0.05,0) -> 720 | N37: =J37-M37 -> -494 | P37: =E37+M37 -> 1538 | Q37: =B37+J37 -> 1081 | R37: =Q37-P37 -> -457 | S37: =IF(R37<0,"$0",(R37*39)) -> $0
A38: Nov | D38: =B38/C38 -> #DIV/0! | E38: =ROUND((C38*5%),0) -> 0 | F38: =B38-E38 -> 0 | I38: Nov | L38: =J38/K38 -> #DIV/0! | M38: =ROUND(K38*0.05,0) -> 0 | N38: =J38-M38 -> 0 | P38: =E38+M38 -> 0 | Q38: =B38+J38 -> 0 | R38: =Q38-P38 -> 0 | S38: =IF(R38<0,"$0",(R38*39)) -> 0
A39: Dec | D39: =B39/C39 -> #DIV/0! | E39: =ROUND((C39*5%),0) -> 0 | F39: =B39-E39 -> 0 | I39: Dec | L39: =J39/K39 -> #DIV/0! | M39: =ROUND(K39*0.05,0) -> 0 | N39: =J39-M39 -> 0 | P39: =E39+M39 -> 0 | Q39: =B39+J39 -> 0 | R39: =Q39-P39 -> 0 | S39: =IF(R39<0,"$0",(R39*39)) -> 0
A44: LCM | I44: Total Overage Trends
A45: Month | B45: RMA Opened | C45: Install base | D45: Actual Incident Rate (5% Contractual) | E45: RMAs Allowed | F45: RMAs Over | G45: Overage $89 | I45: Month | J45: MOC Verifone | K45: MOC Non-Verifone | L45: LCM | M45: Total
A46: Jan | B46: 605 | C46: 10081 | D46: =B46/C46 -> 0.060013888 | E46: =ROUND((C46*1%),0) -> 101 | F46: =B46-E46 -> 504 | G46: =IF(F46<0,"$0",(F46*89)) -> 44856 | I46: Jan | J46: =G3 -> 0 | K46: =O3 -> 0 | L46: =G46 -> 44856 | M46: =SUM(J46:L46) -> 44856
A47: Feb | B47: 470 | C47: 10081 | D47: =B47/C47 -> 0.046622359 | E47: =ROUND((C47*1%),0) -> 101 | F47: =B47-E47 -> 369 | G47: =IF(F47<0,"$0",(F47*89)) -> 32841 | I47: Feb | J47: =G4 -> 0 | K47: =O4 -> 0 | L47: =G47 -> 32841 | M47: =SUM(J47:L47) -> 32841
A48: Mar | B48: 541 | C48: 10174 | D48: =B48/C48 -> 0.053174759 | E48: =ROUND((C48*1%),0) -> 102 | F48: =B48-E48 -> 439 | G48: =IF(F48<0,"$0",(F48*89)) -> 39071 | I48: Mar | J48: =G5 -> 0 | K48: =O5 -> 0 | L48: =G48 -> 39071 | M48: =SUM(J48:L48) -> 39071
A49: Apr | B49: 535 | C49: 10142 | D49: =B49/C49 -> 0.052750937 | E49: =ROUND((C49*1%),0) -> 101 | F49: =B49-E49 -> 434 | G49: =IF(F49<0,"$0",(F49*89)) -> 38626 | I49: Apr | J49: =G6 -> 0 | K49: =O6 -> 0 | L49: =G49 -> 38626 | M49: =SUM(J49:L49) -> 38626
...

Sheet 4. ir_MOC_
A1: Month | B1: Intall Base Non-Verifone | C1: Install Base Verifone | D1: Allowed Tickets | E1: Tickets Over | F1: Actual Tickets Non-Verifone | G1: Actual Tickets Verifone | H1: Contractual IR 5% | I1: Non-Verifone | J1: Verifone | K1: Overall | L1: Overages
A2: Jan | B2: 7000 | C2: 10081 | F2: 215 | G2: 871 | H2: 0.03 | I2: =F2/B2 -> 0.030714286 | J2: =G2/C2 -> 0.086400159 | K2: =(G2+F2)/(C2+B2) -> 0.063579416
A3: Feb | B3: 7000 | C3: 10081 | F3: 218 | G3: 663 | H3: 0.03 | I3: =F3/B3 -> 0.031142857 | J3: =G3/C3 -> 0.065767285 | K3: =(G3+F3)/(C3+B3) -> 0.051577776
A4: Mar | B4: 7000 | C4: 10174 | F4: 276 | G4: 718 | H4: 0.03 | I4: =F4/B4 -> 0.039428571 | J4: =G4/C4 -> 0.070572046 | K4: =(G4+F4)/(C4+B4) -> 0.057878188
A5: Apr | B5: 7000 | C5: 10142 | F5: 288 | G5: 696 | H5: 0.03 | I5: =F5/B5 -> 0.041142857 | J5: =G5/C5 -> 0.068625518 | K5: =(G5+F5)/(C5+B5) -> 0.05740287
A6: May | B6: 7000 | C6: 10428 | F6: 364 | G6: 772 | H6: 0.03 | I6: =F6/B6 -> 0.052 | J6: =G6/C6 -> 0.074031454 | K6: =(G6+F6)/(C6+B6) -> 0.065182465
A7: Jun | B7: 7000 | C7: 10575 | F7: 492 | G7: 853 | H7: 0.03 | I7: =F7/B7 -> 0.070285714 | J7: =G7/C7 -> 0.080661939 | K7: =(G7+F7)/(C7+B7) -> 0.076529161
A8: Jul (old rate) | B8: 7000 | C8: =Overages!C10 -> 10773 | F8: 187 | G8: 504 | H8: 0.03 | I8: =F8/B8 -> 0.026714286 | J8: =G8/C8 -> 0.046783626 | K8: =(G8+F8)/(C8+B8) -> 0.038879199
A9: Jul (new rate) | B9: 12174 | C9: 10773 | F9: 227 | G9: 450 | H9: 0.05 | I9: =F9/B9 -> 0.018646295 | J9: =G9/C9 -> 0.041771094 | K9: =(G9+F9)/(C9+B9) -> 0.029502767
A10: Aug | B10: 12174 | C10: =Overages!C11 -> 11086 | D10: =Overages!E11+Overages!M11 -> 1163 | E10: =F10+G10-D10 -> -45 | F10: =Overages!J11 -> 422 | G10: =Overages!B11 -> 696 | H10: 0.05 | I10: =F10/B10 -> 0.034664038 | J10: =G10/C10 -> 0.062781887 | K10: =(G10+F10)/(C10+B10) -> 0.048065348 | L10: =IF(E10<0,"$0",(E10*39)) -> $0
A11: Sep | B11: 12174 | C11: =Overages!C12 -> 11179 | D11: =Overages!E12+Overages!M12 -> 1168 | E11: =F11+G11-D11 -> -98 | F11: =Overages!J12 -> 488 | G11: =Overages!B12 -> 582 | H11: 0.05 | I11: =F11/B11 -> 0.040085428 | J11: =G11/C11 -> 0.052061902 | K11: =(G11+F11)/(C11+B11) -> 0.045818524 | L11: =IF(E11<0,"$0",(E11*39)) -> $0
A12: Oct | B12: 12174 | C12: =Overages!C13 -> 11304 | D12: =Overages!E13+Overages!M13 -> 1174 | E12: =F12+G12-D12 -> -225 | F12: =Overages!J13 -> 358 | G12: =Overages!B13 -> 591 | H12: 0.05 | I12: =F12/B12 -> 0.029406933 | J12: =G12/C12 -> 0.052282378 | K12: =(G12+F12)/(C12+B12) -> 0.040420819 | L12: =IF(E12<0,"$0",(E12*39)) -> $0
A13: Nov | B13: 12174 | C13: =Overages!C14 -> 11343 | D13: =Overages!E14+Overages!M14 -> 1176 | E13: =F13+G13-D13 -> -84 | F13: =Overages!J14 -> 501 | G13: =Overages!B14 -> 591 | H13: 0.05 | I13: =F13/B13 -> 0.041153277 | J13: =G13/C13 -> 0.052102618 | K13: =(G13+F13)/(C13+B13) -> 0.046434494 | L13: =IF(E13<0,"$0",(E13*39)) -> $0
A14: Dec | B14: 12202 | C14: =Overages!C15 -> 11447 | D14: =Overages!E15+Overages!M15 -> 1182 | E14: =F14+G14-D14 -> -221 | F14: =Overages!J15 -> 314 | G14: =Overages!B15 -> 647 | H14: 0.05 | I14: =F14/B14 -> 0.025733486 | J14: =G14/C14 -> 0.056521359 | K14: =(G14+F14)/(C14+B14) -> 0.040635968 | L14: =IF(E14<0,"$0",(E14*39)) -> $0
A15: Jan | B15: 12202 | C15: 11728 | D15: =Overages!E16+Overages!M16 -> 1196 | E15: =F15+G15-D15 -> -213 | F15: =Overages!J16 -> 276 | G15: =Overages!B16 -> 707 | H15: 0.05 | I15: =F15/B15 -> 0.022619243 | J15: =G15/C15 -> 0.060283083 | K15: =(G15+F15)/(C15+B15) -> 0.041078145 | L15: =IF(E15<0,"$0",(E15*39)) -> $0
A16: Feb | B16: 12202 | C16: 11842 | D16: =Overages!E17+Overages!M17 -> 1202 | E16: =F16+G16-D16 -> -263 | F16: =Overages!J17 -> 226 | G16: =Overages!B17 -> 713 | H16: 0.05 | I16: =F16/B16 -> 0.018521554 | J16: =G16/C16 -> 0.060209424 | K16: =(G16+F16)/(C16+B16) -> 0.039053402 | L16: =IF(E16<0,"$0",(E16*39)) -> $0
A17: Mar | B17: 12202 | C17: 12136 | D17: =Overages!E18+Overages!M18 -> 1217 | E17: =F17+G17-D17 -> -217 | F17: =Overages!J18 -> 156 | G17: =Overages!B18 -> 844 | H17: 0.05 | I17: =F17/B17 -> 0.012784789 | J17: =G17/C17 -> 0.069545155 | K17: =(G17+F17)/(C17+B17) -> 0.041088011 | L17: =IF(E17<0,"$0",(E17*39)) -> $0
A18: Apr | B18: 12202 | C18: 12306 | D18: =Overages!E19+Overages!M19 -> 1225 | E18: =F18+G18-D18 -> -266 | F18: =Overages!J19 -> 135 | G18: =Overages!B19 -> 824 | H18: 0.05 | I18: =F18/B18 -> 0.01106376 | J18: =G18/C18 -> 0.066959207 | K18: =(G18+F18)/(C18+B18) -> 0.03913008 | L18: =IF(E18<0,"$0",(E18*39)) -> $0
A19: May | B19: 12202 | C19: =Overages!C20 -> 12601 | D19: =Overages!E20+Overages!M20 -> 1240 | E19: =F19+G19-D19 -> -325 | F19: =Overages!J20 -> 179 | G19: =Overages!B20 -> 736 | H19: 0.05 | I19: =F19/B19 -> 0.014669726 | J19: =G19/C19 -> 0.058408063 | K19: =(G19+F19)/(C19+B19) -> 0.036890699 | L19: =IF(E19<0,"$0",(E19*39)) -> $0
A20: Jun | B20: =Overages!K21 -> 13060 | C20: =Overages!C21 -> 12740 | D20: =Overages!E21+Overages!M21 -> 1290 | E20: =F20+G20-D20 -> -71 | F20: =Overages!J21 -> 264 | G20: =Overages!B21 -> 955 | H20: 0.05 | I20: =F20/B20 -> 0.020214395 | J20: =G20/C20 -> 0.074960754 | K20: =(G20+F20)/(C20+B20) -> 0.047248062 | L20: =IF(E20<0,"$0",(E20*39)) -> $0
A21: Jul | B21: =Overages!K22 -> 13060 | C21: =Overages!C22 -> 12936 | D21: =Overages!E22+Overages!M22 -> 1300 | E21: =F21+G21-D21 -> 225 | F21: =Overages!J22 -> 582 | G21: =Overages!B22 -> 943 | H21: 0.05 | I21: =F21/B21 -> 0.044563553 | J21: =G21/C21 -> 0.072897341 | K21: =(G21+F21)/(C21+B21) -> 0.058662871 | L21: =IF(E21<0,"$0",(E21*39)) -> 8775
A22: Aug | B22: =Overages!K23 -> 13060 | C22: 13079 | D22: =Overages!E23+Overages!M23 -> 1307 | E22: =F22+G22-D22 -> -41 | F22: =Overages!J23 -> 494 | G22: =Overages!B23 -> 772 | H22: 0.05 | I22: =F22/B22 -> 0.037825421 | J22: =G22/C22 -> 0.059025919 | K22: =(G22+F22)/(C22+B22) -> 0.048433375 | L22: =IF(E22<0,"$0",(E22*39)) -> $0
A23: Sep | B23: =Overages!K24 -> 13060 | C23: =Overages!C24 -> 13515 | D23: =Overages!E24+Overages!M24 -> 1329 | E23: =F23+G23-D23 -> 20 | F23: =Overages!J24 -> 493 | G23: =Overages!B24 -> 856 | H23: 0.05 | I23: =F23/B23 -> 0.037748851 | J23: =G23/C23 -> 0.063337033 | K23: =(G23+F23)/(C23+B23) -> 0.050761994 | L23: =IF(E23<0,"$0",(E23*39)) -> 780
A24: Oct | B24: =Overages!K25 -> 13060 | C24: =Overages!C25 -> 13652 | D24: =Overages!E25+Overages!M25 -> 1336 | E24: =F24+G24-D24 -> -136 | F24: =Overages!J25 -> 445 | G24: =Overages!B25 -> 755 | H24: 0.05 | I24: =F24/B24 -> 0.034073507 | J24: =G24/C24 -> 0.055303252 | K24: =(G24+F24)/(C24+B24) -> 0.04492363 | L24: =IF(E24<0,"$0",(E24*39)) -> $0
A25: Nov | B25: =Overages!K26 -> 13060 | C25: =Overages!C26 -> 13886 | D25: =Overages!E26+Overages!M26 -> 1347 | E25: =F25+G25-D25 -> 237 | F25: =Overages!J26 -> 743 | G25: =Overages!B26 -> 841 | H25: 0.05 | I25: =F25/B25 -> 0.056891271 | J25: =G25/C25 -> 0.060564597 | K25: =(G25+F25)/(C25+B25) -> 0.058784235 | L25: =IF(E25<0,"$0",(E25*39)) -> 9243
A26: Dec | B26: =Overages!K27 -> 13060 | C26: =Overages!C27 -> 14160 | D26: =Overages!E27+Overages!M27 -> 1361 | E26: =F26+G26-D26 -> 100 | F26: =Overages!J27 -> 506 | G26: =Overages!B27 -> 955 | H26: 0.05 | I26: =F26/B26 -> 0.038744257 | J26: =G26/C26 -> 0.067443503 | K26: =(G26+F26)/(C26+B26) -> 0.053673769 | L26: =IF(E26<0,"$0",(E26*39)) -> 3900
A27: Jan | B27: =Overages!K28 -> 14400 | C27: =Overages!C28 -> 14247 | D27: =Overages!E28+Overages!M28 -> 1432 | E27: =F27+G27-D27 -> -10 | F27: =Overages!J28 -> 567 | G27: =Overages!B28 -> 855 | H27: 0.05 | I27: =F27/B27 -> 0.039375 | J27: =G27/C27 -> 0.060012634 | K27: =(G27+F27)/(C27+B27) -> 0.049638706 | L27: =IF(E27<0,"$0",(E27*39)) -> $0
A28: Feb | B28: =Overages!K29 -> 14400 | C28: =Overages!C29 -> 14579 | D28: =Overages!E29+Overages!M29 -> 1449 | E28: =F28+G28-D28 -> 93 | F28: =Overages!J29 -> 659 | G28: =Overages!B29 -> 883 | H28: 0.05 | I28: =F28/B28 -> 0.045763889 | J28: =G28/C28 -> 0.060566568 | K28: =(G28+F28)/(C28+B28) -> 0.053210946 | L28: =IF(E28<0,"$0",(E28*39)) -> 3627
A29: Mar | B29: =Overages!K30 -> 14400 | C29: =Overages!C30 -> 14831 | D29: =Overages!E30+Overages!M30 -> 1462 | E29: =F29+G29-D29 -> -5 | F29: =Overages!J30 -> 585 | G29: =Overages!B30 -> 872 | H29: 0.05 | I29: =F29/B29 -> 0.040625 | J29: =G29/C29 -> 0.058795766 | K29: =(F29+G29)/(B29+C29) -> 0.049844343 | L29: =IF(E29<0,"$0",(E29*39)) -> $0
A30: Apr | B30: =Overages!K31 -> 14400 | C30: =Overages!C31 -> 15033 | D30: =Overages!E31+Overages!M31 -> 1472 | E30: =F30+G30-D30 -> 116 | F30: =Overages!J31 -> 614 | G30: =Overages!B31 -> 974 | H30: 0.05 | I30: =F30/B30 -> 0.042638889 | J30: =G30/C30 -> 0.064790794 | K30: =(G30+F30)/(C30+B30) -> 0.053953046 | L30: =IF(E30<0,"$0",(E30*39)) -> 4524
A31: May | B31: =Overages!K32 -> 14400 | C31: =Overages!C32 -> 15194 | D31: =Overages!E32+Overages!M32 -> 1480 | E31: =F31+G31-D31 -> 317 | F31: =Overages!J32 -> 784 | G31: =Overages!B32 -> 1013 | H31: 0.05 | I31: =F31/B31 -> 0.054444444 | J31: =G31/C31 -> 0.066671054 | K31: =(G31+F31)/(C31+B31) -> 0.060721768 | L31: =IF(E31<0,"$0",(E31*39)) -> 12363
A32: Jun | B32: =Overages!K33 -> 14400 | C32: =Overages!C33 -> 15471 | D32: =Overages!E33+Overages!M33 -> 1494 | E32: =F32+G32-D32 -> 338 | F32: =Overages!J33 -> 831 | G32: =Overages!B33 -> 1001 | H32: 0.05 | I32: =F32/B32 -> 0.057708333 | J32: =G32/C32 -> 0.0647017 | K32: =(G32+F32)/(C32+B32) -> 0.061330387 | L32: =IF(E32<0,"$0",(E32*39)) -> 13182
A33: Jul | B33: =Overages!K34 -> 14400 | C33: =Overages!C34 -> 15926 | D33: =Overages!E34+Overages!M34 -> 1516 | E33: =F33+G33-D33 -> 596 | F33: =Overages!J34 -> 849 | G33: =Overages!B34 -> 1263 | H33: 0.05 | I33: =F33/B33 -> 0.058958333 | J33: =G33/C33 -> 0.079304282 | K33: =(G33+F33)/(C33+B33) -> 0.06964321 | L33: =IF(E33<0,"$0",(E33*39)) -> 23244
A34: Aug | B34: =Overages!K35 -> 14400 | C34: =Overages!C35 -> 16151 | D34: =Overages!E35+Overages!M35 -> 1528 | E34: =F34+G34-D34 -> 453 | F34: =Overages!J35 -> 707 | G34: =Overages!B35 -> 1274 | H34: 0.05 | I34: =F34/B34 -> 0.049097222 | J34: =G34/C34 -> 0.078880565 | K34: =(G34+F34)/(C34+B34) -> 0.064842395 | L34: =IF(E34<0,"$0",(E34*39)) -> 17667
A35: Sep | B35: =Overages!K36 -> 14400 | C35: =Overages!C36 -> 16354 | D35: =Overages!E36+Overages!M36 -> 1538 | E35: =F35+G35-D35 -> 430 | F35: =Overages!J36 -> 829 | G35: =Overages!B36 -> 1139 | H35: 0.05 | I35: =F35/B35 -> 0.057569444 | J35: =G35/C35 -> 0.06964657 | K35: =(G35+F35)/(C35+B35) -> 0.063991676 | L35: =IF(E35<0,"$0",(E35*39)) -> 16770
A36: Oct | B36: =Overages!K37 -> 14400 | C36: =Overages!C37 -> 16354 | D36: =Overages!E37+Overages!M37 -> 1538 | E36: =F36+G36-D36 -> -457 | F36: =Overages!J37 -> 226 | G36: =Overages!B37 -> 855 | H36: 0.05 | I36: =F36/B36 -> 0.015694444 | J36: =G36/C36 -> 0.052280788 | K36: =(G36+F36)/(C36+B36) -> 0.035149899 | L36: =IF(E36<0,"$0",(E36*39)) -> $0
A37: Nov | B37: =Overages!K38 -> 0 | C37: =Overages!C38 -> 0 | D37: =Overages!E38+Overages!M38 -> 0 | E37: =F37+G37-D37 -> 0 | F37: =Overages!J38 -> 0 | G37: =Overages!B38 -> 0 | H37: 0.05 | I37: =F37/B37 -> #DIV/0! | J37: =G37/C37 -> #DIV/0! | K37: =(G37+F37)/(C37+B37) -> #DIV/0! | L37: =IF(E37<0,"$0",(E37*39)) -> 0
A38: Dec | B38: =Overages!K39 -> 0 | C38: =Overages!C39 -> 0 | D38: =Overages!E39+Overages!M39 -> 0 | E38: =F38+G38-D38 -> 0 | F38: =Overages!J39 -> 0 | G38: =Overages!B39 -> 0 | H38: 0.05 | I38: =F38/B38 -> #DIV/0! | J38: =G38/C38 -> #DIV/0! | K38: =(G38+F38)/(C38+B38) -> #DIV/0! | L38: =IF(E38<0,"$0",(E38*39)) -> 0
A39: Total | F39: =SUM(F15:F26) -> 4499 | G39: =SUM(G15:G26) -> 9901 | I39: =AVERAGE(I15:I26) -> 0.029143361 | J39: =AVERAGE(J15:J26) -> 0.064078111 | K39: =AVERAGE(K15:K26) -> 0.046644023

Sheet 4. ir_LCM
A1: Month | B1: Install Base Verifone | C1: Actual RMAs Verifone | D1: Contractual IR 5% | E1: Verifone
A2: Jan | B2: 10081 | C2: 602 | D2: 0.01 | E2: =C2/B2 -> 0.059716298
A3: Feb | B3: 10081 | C3: 472 | D3: 0.01 | E3: =C3/B3 -> 0.046820752
A4: Mar | B4: 10174 | C4: 547 | D4: 0.01 | E4: =C4/B4 -> 0.053764498
A5: Apr | B5: 10142 | C5: 546 | D5: 0.01 | E5: =C5/B5 -> 0.053835535
A6: May | B6: 10428 | C6: 519 | D6: 0.01 | E6: =C6/B6 -> 0.04976985
A7: Jun | B7: 10575 | C7: 572 | D7: 0.01 | E7: =C7/B7 -> 0.054089835
A8: Jul (old rate) | B8: =[2]Overages!C26 -> 10773 | C8: =[2]Overages!B26 -> 330 | D8: 0.01 | E8: =C8/B8 -> 0.030632136
A9: Jul (new rate) | B9: =[2]Overages!C27 -> 10773 | C9: =[2]Overages!B27 -> 334 | D9: 0.05 | E9: =C9/B9 -> 0.031003435
A10: Aug | B10: =[2]Overages!C28 -> 11055 | C10: =Overages!B54 -> 554 | D10: 0.05 | E10: =C10/B10 -> 0.050113071
A11: Sep | B11: =Overages!C55 -> 11179 | C11: =Overages!B55 -> 523 | D11: 0.05 | E11: =C11/B11 -> 0.046784149
A12: Oct | B12: =Overages!C56 -> 11304 | C12: =Overages!B56 -> 551 | D12: 0.05 | E12: =C12/B12 -> 0.048743808
A13: Nov | B13: =Overages!C57 -> 11343 | C13: =Overages!B57 -> 499 | D13: 0.05 | E13: =C13/B13 -> 0.043991889
A14: Dec | B14: =Overages!C58 -> 11447 | C14: =Overages!B58 -> 612 | D14: 0.05 | E14: =C14/B14 -> 0.05346379
A15: Jan | B15: 11728 | C15: =Overages!B59 -> 606 | D15: 0.05 | E15: =C15/B15 -> 0.051671214
A16: Feb | B16: 11842 | C16: =Overages!B60 -> 637 | D16: 0.05 | E16: =C16/B16 -> 0.053791589
A17: Mar | B17: 12136 | C17: 709 | D17: 0.05 | E17: =C17/B17 -> 0.058421226
A18: Apr | B18: 12306 | C18: =Overages!B62 -> 783 | D18: 0.05 | E18: =C18/B18 -> 0.063627499
A19: May | B19: =Overages!C63 -> 12601 | C19: =Overages!B63 -> 670 | D19: 0.05 | E19: =C19/B19 -> 0.053170383
A20: June | B20: =Overages!C64 -> 12740 | C20: =Overages!B64 -> 793 | D20: 0.05 | E20: =C20/B20 -> 0.062244898
A21: July | B21: =Overages!C65 -> 12936 | C21: =Overages!B65 -> 851 | D21: 0.05 | E21: =C21/B21 -> 0.065785405
A22: Aug | B22: =Overages!C66 -> 13079 | C22: =Overages!B66 -> 669 | D22: 0.05 | E22: =C22/B22 -> 0.0511507
A23: Sep | B23: =Overages!C67 -> 13515 | C23: =Overages!B67 -> 811 | D23: 0.05 | E23: =C23/B23 -> 0.060007399
A24: Oct | B24: =Overages!C68 -> 13652 | C24: =Overages!B68 -> 716 | D24: 0.05 | E24: =C24/B24 -> 0.052446528
A25: Nov | B25: =Overages!C69 -> 13886 | C25: =Overages!B69 -> 731 | D25: 0.05 | E25: =C25/B25 -> 0.05264295
A26: Dec | B26: =Overages!C70 -> 14160 | C26: =Overages!B70 -> 799 | D26: 0.05 | E26: =C26/B26 -> 0.056426554
A27: Jan | B27: =Overages!C71 -> 14247 | C27: =Overages!B71 -> 890 | D27: 0.05 | E27: =C27/B27 -> 0.062469292
A28: Feb | B28: =Overages!C72 -> 14579 | C28: =Overages!B72 -> 828 | D28: 0.05 | E28: =C28/B28 -> 0.056794019
A29: Mar | B29: =Overages!C73 -> 14831 | C29: =Overages!B73 -> 815 | D29: 0.05 | E29: =C29/B29 -> 0.054952464
A30: Apr | B30: =Overages!C74 -> 15033 | C30: =Overages!B74 -> 985 | D30: 0.05 | E30: =C30/B30 -> 0.065522517
... A38: Dec | B38: =Overages!C82 -> 0 | C38: =Overages!B82 -> 0 | D38: 0.05 | E38: =C38/B38 -> #DIV/0!
A39: Total | C39: =SUM(C15:C26) -> 8775 | E39: =AVERAGE(E15:E26) -> 0.056782195

Sheet Install Base
A1: Final install base for each month is calculated on the 1st business day of the month following using all assets that show as "In the field", in "Spare Pool" and customer owned devices that are being held prior to reshipment when the shop wasn't able to accept the original shipment.
A2: Month | B2: Install base | C2: E285s Shipped
A3: Jan | B3: 14247
A4: Feb | B4: 14579
A5: Mar | B5: 14831
A6: Apr | B6: 15033
A7: May | B7: 15194
A8: Jun | B8: 15471
A9: Jul | B9: 15926
A10: 46237 | B10: =SUM(B9+C10) -> 15951 | C10: 25
A11: 46244 | B11: =SUM(B10+C11) -> 15996 | C11: 45
A12: 46251 | B12: =SUM(B11+C12) -> 16041 | C12: 45
A13: 46258 | B13: =SUM(B12+C13) -> 16151 | C13: 110
A14: Aug Final | B14: 16151
A15: 46266 | B15: =SUM(B14+C15) -> 16221 | C15: 70
A16: 46272 | B16: =SUM(B15+C16) -> 16231 | C16: 10
A17: 46279 | B17: =SUM(B16+C17) -> 16312 | C17: 81
A18: 46286 | B18: =SUM(B17+C18) -> 16332 | C18: 20
A19: 46293 | B19: =SUM(B18+C19) -> 16352 | C19: 20
A20: Replacements | B20: =SUM(B19+C20) -> 16354 | C20: 2
A21: Sep Final | B21: 16354
A22: 46296 | B22: =SUM(B21+C22) -> 16354 | C22: 0
A23: 46300 | B23: =SUM(B22+C23) -> 16374 | C23: 20
A24: 46307 | B24: =SUM(B23+C24) -> 16444 | C24: 70
A25: 46314 | B25: =SUM(B24+C25) -> 16494 | C25: 50
A26: 46321 | B26: =SUM(B25+C26) -> 16494

Sheet OEM Replacments
A1: Date Replaced | B1: Returned Serial | C1: Replacement Serial
A2: 46267.503 | B2: 806-318-265 | C2: 807-183-350
A3: 46267.429 | B3: 807-188-534 | C3: 807-529-493
A4: 46111.628 | B4: 807-256-076 | C4: 860-118-785
A5: 46111.625 | B5: 807-233-026 | C5: 402-005-596
A6: 46111.621 | B6: 807-050-217 | C6: 805-918-462
A7: 46111.617 | B7: 807-239-947 | C7: 860-058-581
A8: 46111.606 | B8: 807-280-393 | C8: 809-002-768
A9: 46105.55 | B9: 807-280-034 | C9: 807-183-340
A10: 46105.544 | B10: 807-363-530 | C10: 402-004-873
A11: 46071.424 | B11: 807-188-474 | C11: 807-555-333
A12: 46071.41 | B12: 807-074-995 | C12: 860-129-442
A13: 46071.384 | B13: 807-245-447 | C13: 805-156-797
... A15: 46070.692 | B15: 806-987-206 | C15: 806-318-368

Sheet MOC Data
A1: Ticket # | B1: Title | C1: Last Activity Date | D1: Opened | E1: Status | F1: Trouble Type | G1: Subtype | H1: Symptom | I1: Root Cause | J1: Solution | K1: Element | L1: Company | M1: Caller Employee Number | N1: RMA # | O1: Device Type | P1: Contact Type
A2: INC4854017 | B2: Dutch Bros Verifone -- Inquiry/ Help -- Assistance Request -- Ticket Status | C2: 46312.5 | D2: 46310.885 | E2: Closed | F2: Inquiry/ Help | G2: Assistance Request | H2: Ticket Status | I2: Ticket Status Request | J2: Provided Ticket Status | K2: Inquiry | L2: Dutch Bros Verifone | M2: DO NOT MODIFY THIS RECORD!!!! | O2: e285 | P2: Email
A3: INC4854016 | B3: Dutch Bros Verifone -- Hardware -- Verifone E285 -- Unable to Pair | C3: 46312.5 | D3: 46310.885 | E3: Closed | F3: Hardware | G3: Verifone E285 | H3: Unable to Pair | I3: Bluetooth/Pairing Issue | J3: RMA | K3: Hardware Issue | L3: Dutch Bros Verifone | M3: DO NOT MODIFY THIS RECORD!!!! | N3: 15820458 | O3: e285 | P3: Email
A4: INC4854005 | B4: Dutch Bros Verifone -- Inquiry/ Help -- Assistance Request -- Ticket Status | C4: 46312.458 | D4: 46310.853 | E4: Closed | F4: Inquiry/ Help | G4: Assistance Request | H4: Ticket Status | I4: Ticket Status Request | J4: Provided Ticket Status | K4: Inquiry | L4: Dutch Bros Verifone | M4: DO NOT MODIFY THIS RECORD!!!! | O4: e285 | P4: Email
A5: INC4854004 | B5: Dutch Bros Verifone -- Hardware -- Verifone E285 -- Physical Damage | C5: 46312.5 | D5: 46310.853 | E5: Closed | F5: Hardware | G5: Verifone E285 | H5: Physical Damage | I5: Physical Damage to Housing | J5: RMA | K5: Hardware Issue | L5: Dutch Bros Verifone | M5: DO NOT MODIFY THIS RECORD!!!! | N5: 15820646 | O5: e285 | P5: Email
A6: INC4853922 | B6: Dutch Bros Verifone -- Inquiry/ Help -- Assistance Request -- Ticket Status | C6: 46312.458 | D6: 46310.77 | E6: Closed | F6: Inquiry/ Help | G6: Assistance Request | H6: Ticket Status | I6: Ticket Status Request | J6: Provided Ticket Status | K6: Inquiry | L6: Dutch Bros Verifone | M6: DO NOT MODIFY THIS RECORD!!!! | O6: e285 | P6: Email
A7: INC4853921 | B7: Dutch Bros Verifone -- Hardware -- Verifone E285 -- Physical Damage | C7: 46312.5 | D7: 46310.77 | E7: Closed | F7: Hardware | G7: Verifone E285 | H7: Physical Damage | I7: Damaged Charging Port | J7: RMA | K7: Hardware Issue | L7: Dutch Bros Verifone | M7: DO NOT MODIFY THIS RECORD!!!! | N7: 15820446 | O7: e285 | P7: Email
A8: INC4853829 | B8: Dutch Bros Verifone -- Inquiry/ Help -- Assistance Request -- Ticket Status | C8: 46312.458 | D8: 46310.725 | E8: Closed | F8: Inquiry/ Help | G8: Assistance Request | H8: Ticket Status | I8: Ticket Status Request | J8: Provided Ticket Status | K8: Inquiry | L8: Dutch Bros Verifone | M8: DO NOT MODIFY THIS RECORD!!!! | O8: e285 | P8: Email
A9: INC4853828 | B9: Dutch Bros Verifone -- Inquiry/ Help -- Assistance Request -- Ticket Status | C9: 46312.458 | D9: 46310.725 | E9: Closed | F9: Inquiry/ Help | G9: Assistance Request | H9: Ticket Status | I9: Ticket Status Request | J9: Provided Ticket Status | K9: Inquiry | L9: Dutch Bros Verifone | M9: DO NOT MODIFY THIS RECORD!!!! | O9: e285 | P9: Email
A10: INC4853827 | B10: Dutch Bros Verifone -- Inquiry/ Help -- Assistance Request -- Ticket Status | C10: 46312.458 | D10: 46310.725 | E10: Closed | F10: Inquiry/ Help | G10: Assistance Request | H10: Ticket Status | I10: Ticket Status Request | J10: Provided Ticket Status | K10: Inquiry | L10: Dutch Bros Verifone | M10: DO NOT MODIFY THIS RECORD!!!! | O10: e285 | P10: Email
A11: INC4853826 | B11: Dutch Bros Verifone -- Inquiry/ Help -- Assistance Request -- Ticket Status | C11: 46312.458 | D11: 46310.725 | E11: Closed | F11: Inquiry/ Help | G11: Assistance Request | H11: Ticket Status | I11: Ticket Status Request | J11: Provided Ticket Status | K11: Inquiry | L11: Dutch Bros Verifone | M11: DO NOT MODIFY THIS RECORD!!!! | O11: e285 | P11: Email
A12: INC4853823 | B12: Dutch Bros Verifone -- Inquiry/ Help -- Assistance Request -- Ticket Status | C12: 46312.458 | D12: 46310.725 | E12: Closed | F12: Inquiry/ Help | G12: Assistance Request | H12: Ticket Status | I12: Ticket Status Request | J12: Provided Ticket Status | K12: Inquiry | L12: Dutch Bros Verifone | M12: DO NOT MODIFY THIS RECORD!!!! | O12: e285 | P12: Email
A13: INC4853822 | B13: Dutch Bros Verifone -- Hardware -- Verifone E285 -- Physical Damage | C13: 46312.5 | D13: 46310.725 | E13: Closed | F13: Hardware | G13: Verifone E285 | H13: Physical Damage | I13: Damaged Charging Port | J13: RMA | K13: Hardware Issue | L13: Dutch Bros Verifone | M13: DO NOT MODIFY THIS RECORD!!!! | N13: 15820296 | O13: e285 | P13: Email
A14: INC4853821 | B14: Dutch Bros Verifone -- Hardware -- Verifone E285 -- Lost/ Stolen | C14: 46312.458 | D14: 46310.725 | E14: Closed | F14: Hardware | G14: Verifone E285 | H14: Lost/ Stolen | I14: Device Lost | J14: Processed lost/stolen RMA | K14: Hardware Issue | L14: Dutch Bros Verifone | M14: DO NOT MODIFY THIS RECORD!!!! | N14: 15820286 | O14: e285 | P14: Email
A15: INC4853820 | B15: Dutch Bros Verifone -- Hardware -- Verifone E285 -- Physical Damage | C15: 46312.5 | D15: 46310.725 | E15: Closed | F15: Hardware | G15: Verifone E285 | H15: Physical Damage | I15: Damaged Charging Port | J15: RMA | K15: Hardware Issue | L15: Dutch Bros Verifone | M15: DO NOT MODIFY THIS RECORD!!!! | N15: 15820442 | O15: e285 | P15: Email
A16: INC4853819 | B16: Dutch Bros Verifone -- Hardware -- Verifone E285 -- Lost/ Stolen | C16: 46312.458 | D16: 46310.725 | E16: Closed | F16: Hardware | G16: Verifone E285 | H16: Lost/ Stolen | I16: Device Lost | J16: Processed lost/stolen RMA | K16: Hardware Issue | L16: Dutch Bros Verifone | M16: DO NOT MODIFY THIS RECORD!!!! | N16: 15820066 | O16: e285 | P16: Email
A17: INC4853818 | B17: Dutch Bros Verifone -- Hardware -- Verifone E285 -- Physical Damage | C17: 46312.458 | D17: 46310.725 | E17: Closed | F17: Hardware | G17: Verifone E285 | H17: Physical Damage | I17: Physical Damage to Housing | J17: RMA | K17: Hardware Issue | L17: Dutch Bros Verifone | M17: DO NOT MODIFY THIS RECORD!!!! | N17: 15820054 | O17: e285 | P17: Email
A18: INC4853743 | B18: Dutch Bros Verifone -- Hardware -- Verifone E285 -- Tampered device | C18: 46312.458 | D18: 46310.703 | E18: Closed | F18: Hardware | G18: Verifone E285 | H18: Tampered device | I18: Device in Tamper mode | J18: Processed RMA | K18: Hardware Issue | L18: Dutch Bros Verifone | M18: DO NOT MODIFY THIS RECORD!!!! | N18: 15820040 | O18: e285 | P18: Email
A19: INC4853591 | B19: Dutch Bros Verifone -- Inquiry/ Help -- Assistance Request -- Ticket Status | C19: 46312.417 | D19: 46310.651 | E19: Closed | F19: Inquiry/ Help | G19: Assistance Request | H19: Ticket Status | I19: Ticket Status Request | J19: Provided Ticket Status | K19: Inquiry | L19: Dutch Bros Verifone | M19: DO NOT MODIFY THIS RECORD!!!! | O19: e285 | P19: Email
A20: INC4853588 | B20: Dutch Bros Verifone -- Hardware -- Verifone E285 -- Won't power on | C20: 46312.417 | D20: 46310.651 | E20: Closed | F20: Hardware | G20: Verifone E285 | H20: Won't power on | I20: Power Issue | J20: RMA | K20: Hardware Issue | L20: Dutch Bros Verifone | M20: DO NOT MODIFY THIS RECORD!!!! | N20: 15819890 | O20: e285 | P20: Email
A21: INC4853587 | B21: Dutch Bros Verifone -- Inquiry/ Help -- Assistance Request -- Ticket Status | C21: 46312.417 | D21: 46310.651 | E21: Closed | F21: Inquiry/ Help | G21: Assistance Request | H21: Ticket Status | I21: Ticket Status Request | J21: Provided Ticket Status | K21: Inquiry | L21: Dutch Bros Verifone | M21: DO NOT MODIFY THIS RECORD!!!! | O21: e285 | P21: Email
A22: INC4853586 | B22: Dutch Bros Verifone -- Hardware -- Verifone E285 -- Won't power on | C22: 46312.417 | D22: 46310.651 | E22: Closed | F22: Hardware | G22: Verifone E285 | H22: Won't power on | I22: Power Issue | J22: RMA | K22: Hardware Issue | L22: Dutch Bros Verifone | M22: DO NOT MODIFY THIS RECORD!!!! | N22: 15819882 | O22: e285 | P22: Email
A23: INC4853529 | B23: Dutch Bros Verifone -- Inquiry/ Help -- Assistance Request -- Ticket Status | C23: 46312.417 | D23: 46310.635 | E23: Closed | F23: Inquiry/ Help | G23: Assistance Request | H23: Ticket Status | I23: Ticket Status Request | J23: Provided Ticket Status | K23: Inquiry | L23: Dutch Bros Verifone | M23: DO NOT MODIFY THIS RECORD!!!! | O23: e285 | P23: Email
A24: INC4853527 | B24: Dutch Bros Verifone -- Hardware -- Verifone E285 -- Won't power on | C24: 46312.417 | D24: 46310.635 | E24: Closed | F24: Hardware | G24: Verifone E285 | H24: Won't power on | I24: Power Issue | J24: RMA | K24: Hardware Issue | L24: Dutch Bros Verifone | M24: DO NOT MODIFY THIS RECORD!!!! | N24: 15819880 | O24: e285 | P24: Email
A25: INC4853525 | B25: Dutch Bros Verifone -- Inquiry/ Help -- Assistance Request -- Ticket Status | C25: 46312.417 | D25: 46310.635 | E25: Closed | F25: Inquiry/ Help | G25: Assistance Request | H25: Ticket Status | I25: Ticket Status Request | J25: Provided Ticket Status | K25: Inquiry | L25: Dutch Bros Verifone | M25: DO NOT MODIFY THIS RECORD!!!! | O25: e285 | P25: Email
A26: INC4853524 | B26: Dutch Bros Verifone -- Inquiry/ Help -- Assistance Request -- Ticket Status | C26: 46312.417 | D26: 46310.635 | E26: Closed | F26: Inquiry/ Help | G26: Assistance Request | H26: Ticket Status | I26: Ticket Status Request | J26: Provided Ticket Status | K26: Inquiry | L26: Dutch Bros Verifone | M26: DO NOT MODIFY THIS RECORD!!!! | O26: e285 | P26: Email
A27: INC4853522 | B27: Dutch Bros Verifone -- Hardware -- Verifone E285 -- Won't power on | C27: 46312.417 | D27: 46310.635 | E27: Closed | F27: Hardware | G27: Verifone E285 | H27: Won't power on | I27: Power Issue | J27: RMA | K27: Hardware Issue | L27: Dutch Bros Verifone | M27: DO NOT MODIFY THIS RECORD!!!! | N27: 15819862 | O27: e285 | P27: Email
A28: INC4853523 | B28: Dutch Bros Verifone -- Hardware -- Verifone E285 -- Won't power on | C28: 46312.417 | D28: 46310.635 | E28: Closed | F28: Hardware | G28: Verifone E285 | H28: Won't power on | I28: Power Issue | J28: RMA | K28: Hardware Issue | L28: Dutch Bros Verifone | M28: DO NOT MODIFY THIS RECORD!!!! | N28: 15819840 | O28: e285 | P28: Email
A29: INC4853496 | B29: Dutch Bros Verifone -- Inquiry/ Help -- Assistance Request -- Ticket Status | C29: 46312.292 | D29: 46310.628 | E29: Closed | F29: Inquiry/ Help | G29: Assistance Request | H29: Ticket Status | I29: Ticket Status Request | J29: Provided Ticket Status | K29: Inquiry | L29: Dutch Bros Verifone | M29: DB00 | O29: e285 | P29: Email
A30: INC4853495 | B30: Dutch Bros Verifone -- Inquiry/ Help -- Assistance Request -- Ticket Status | C30: 46312.292 | D30: 46310.628 | E30: Closed | F30: Inquiry/ Help | G30: Assistance Request | H30: Ticket Status | I30: Ticket Status Request | J30: Provided Ticket Status | K30: Inquiry | L30: Dutch Bros Verifone | M30: DB00 | O30: e285 | P30: Email
A31: INC4853494 | B31: Dutch Bros Verifone -- Inquiry/ Help -- Assistance Request -- Ticket Status | C31: 46312.292 | D31: 46310.628 | E31: Closed | F31: Inquiry/ Help | G31: Assistance Request | H31: Ticket Status | I31: Ticket Status Request | J31: Provided Ticket Status | K31: Inquiry | L31: Dutch Bros Verifone | M31: DB00 | O31: e285 | P31: Email
A32: INC4853493 | B32: Dutch Bros Verifone -- Inquiry/ Help -- Assistance Request -- Ticket Status | C32: 46312.292 | D32: 46310.628 | E32: Closed | F32: Inquiry/ Help | G32: Assistance Request | H32: Ticket Status | I32: Ticket Status Request | J32: Provided Ticket Status | K32: Inquiry | L32: Dutch Bros Verifone | M32: DB00 | O32: e285 | P32: Email
A33: INC4853492 | B33: Dutch Bros Verifone -- Inquiry/ Help -- Assistance Request -- Ticket Status | C33: 46312.292 | D33: 46310.628 | E33: Closed | F33: Inquiry/ Help | G33: Assistance Request | H33: Ticket Status | I33: Ticket Status Request | J33: Provided Ticket Status | K33: Inquiry | L33: Dutch Bros Verifone | M33: DB00 | O33: e285 | P33: Email
A34: INC4853490 | B34: Dutch Bros Verifone -- Inquiry/ Help -- Assistance Request -- Ticket Status | C34: 46312.292 | D34: 46310.628 | E34: Closed | F34: Inquiry/ Help | G34: Assistance Request | H34: Ticket Status | I34: Ticket Status Request | J34: Provided Ticket Status | K34: Inquiry | L34: Dutch Bros Verifone | M34: DB00 | O34: e285 | P34: Email
A35: INC4853491 | B35: Dutch Bros Verifone -- Inquiry/ Help -- Assistance Request -- Ticket Status | C35: 46312.292 | D35: 46310.628 | E35: Closed | F35: Inquiry/ Help | G35: Assistance Request | H35: Ticket Status | I35: Ticket Status Request | J35: Provided Ticket Status | K35: Inquiry | L35: Dutch Bros Verifone | M35: DB00 | O35: e285 | P35: Email
A36: INC4853489 | B36: Dutch Bros Verifone -- Inquiry/ Help -- Assistance Request -- Ticket Status | C36: 46312.292 | D36: 46310.628 | E36: Closed | F36: Inquiry/ Help | G36: Assistance Request | H36: Ticket Status | I36: Ticket Status Request | J36: Provided Ticket Status | K36: Inquiry | L36: Dutch Bros Verifone | M36: DB00 | O36: e285 | P36: Email
A37: INC4853488 | B37: Dutch Bros Verifone -- Inquiry/ Help -- Assistance Request -- Ticket Status | C37: 46312.292 | D37: 46310.628 | E37: Closed | F37: Inquiry/ Help | G37: Assistance Request | H37: Ticket Status | I37: Ticket Status Request | J37: Provided Ticket Status | K37: Inquiry | L37: Dutch Bros Verifone | M37: DB00 | O37: e285 | P37: Email
A38: INC4853487 | B38: Dutch Bros Verifone -- Inquiry/ Help -- Assistance Request -- Ticket Status | C38: 46312.292 | D38: 46310.627 | E38: Closed | F38: Inquiry/ Help | G38: Assistance Request | H38: Ticket Status | I38: Ticket Status Request | J38: Provided Ticket Status | K38: Inquiry | L38: Dutch Bros Verifone | M38: DB00 | O38: e285 | P38: Email
A39: INC4853471 | B39: Dutch Bros Verifone -- Inquiry/ Help -- Assistance Request -- Ticket Status | C39: 46312.417 | D39: 46310.622 | E39: Closed | F39: Inquiry/ Help | G39: Assistance Request | H39: Ticket Status | I39: Ticket Status Request | J39: Provided Ticket Status | K39: Inquiry | L39: Dutch Bros Verifone | M39: DO NOT MODIFY THIS RECORD!!!! | O39: e285 | P39: Email
A40: INC4853464 | B40: Dutch Bros Verifone -- Hardware -- Verifone E285 -- Physical Damage | C40: 46312.417 | D40: 46310.619 | E40: Closed | F40: Hardware | G40: Verifone E285 | H40: Physical Damage | I40: Water Damage | J40: RMA | K40: Hardware Issue | L40: Dutch Bros Verifone | M40: DO NOT MODIFY THIS RECORD!!!! | O40: e285 | P40: Email
...

Sheet LCM_Data
A1: NewCo ID | B1: RMA # | C1: Status | D1: Due Back Days Aged | E1: Opened | F1: Closed | G1: Reported Failure | H1: Reported Device | I1: Reported Model | J1: Reported Serial # | K1: Reported Asset Tag | L1: Reported Tracking # | M1: Requestor | N1: Reported Repair Type | O1: Returned Date | P1: Returned Tracking # | Q1: Shipped Date | R1: Shipped Tracking # | S1: Ship To Contact First Name | T1: Ship To Contact Last Name
A2: 15780194 | B2: Pending Return | C2: 46306.426 | E2: DAMAGE - Charging Port Damaged | F2: E285 WWA Payment Device (WiFi,512MB) | G2: M087-500-14-WWA | H2: 807-258-983 | K2: Lakisha Hopson | L2: Advanced Exchange | Q2: Brian | R2: Place | S2: Dutch Bros CA1501 | T2: Dutch Bros CA1501
A3: 15769810 | B3: RMA Requested | C3: 46304.755 | E3: ISF - Non-Functioning Hardware | F3: E285 WWA Payment Device (WiFi,512MB) | G3: M087-500-14-WWA | H3: 807-226-102 | K3: System Administrator | L3: Internal Staging Failure
A4: 15768416 | B4: Pending Return | C4: 46304.631 | E4: HARD - Battery Problem | F4: E285 WWA Payment Device (WiFi,512MB) | G4: M087-500-14-WWA | H4: 807-259-232 | K4: Mata Hann | L4: Advanced Exchange | Q4: Sean | R4: Provost | S4: Dutch Bros CA2506 | T4: Dutch Bros CA2506
A5: 15768260 | B5: Pending Return | C5: 46304.621 | E5: DAMAGE - Tamper Detected | F5: E285 WWA Payment Device (WiFi,512MB) | G5: M087-500-14-WWA | H5: 807-262-829 | K5: Mata Hann | L5: Advanced Exchange | Q5: Haley | R5: Jones | S5: Dutch Bros CA3002 | T5: Dutch Bros CA3002
A6: 15768224 | B6: Pending Return | C6: 46304.615 | E6: DAMAGE - Tamper Detected | F6: E285 WWA Payment Device (WiFi,512MB) | G6: M087-500-14-WWA | H6: 807-074-549 | K6: Mata Hann | L6: Advanced Exchange | Q6: Mark | R6: Essey | S6: Dutch Bros UT0605 | T6: Dutch Bros UT0605
A7: 15768200 | B7: Pending Return | C7: 46304.608 | E7: DAMAGE - Tamper Detected | F7: E285 WWA Payment Device (WiFi,512MB) | G7: M087-500-14-WWA | H7: 807-259-412 | K7: Mata Hann | L7: Advanced Exchange | Q7: Meredith | R7: Ignacio | S7: Dutch Bros CA0807 | T7: Dutch Bros CA0807
A8: 15768030 | B8: Pending Return | C8: 46304.601 | E8: DAMAGE - Tamper Detected | F8: E285 WWA Payment Device (WiFi,512MB) | G8: M087-500-14-WWA | H8: 807-554-785 | K8: Mata Hann | L8: Advanced Exchange | Q8: Kenny | R8: Hiler | S8: Dutch Bros #OR0607 | T8: Dutch Bros #OR0607
A9: 15768022 | B9: Pending Return | C9: 46304.593 | E9: DAMAGE - Physical Damage to Housing | F9: E285 WWA Payment Device (WiFi,512MB) | G9: M087-500-14-WWA | H9: 807-210-209 | K9: Mata Hann | L9: Advanced Exchange | Q9: Kenny | R9: Hiler | S9: Dutch Bros #OR0607 | T9: Dutch Bros #OR0607
A10: 15767880 | B10: Pending Return | C10: 46304.584 | E10: DAMAGE - Tamper Detected | F10: E285 WWA Payment Device (WiFi,512MB) | G10: M087-500-14-WWA | H10: 807-256-488 | K10: Mata Hann | L10: Advanced Exchange | Q10: Kenny | R10: Hiler | S10: Dutch Bros #OR0607 | T10: Dutch Bros #OR0607
A11: 15767852 | B11: Pending Return | C11: 46304.581 | E11: DAMAGE - Physical Damage to Housing | F11: E285 WWA Payment Device (WiFi,512MB) | G11: M087-500-14-WWA | H11: 806-764-475 | K11: Mata Hann | L11: Advanced Exchange | Q11: Kenny | R11: Hiler | S11: Dutch Bros #OR0607 | T11: Dutch Bros #OR0607
A12: 15767792 | B12: Pending Return | C12: 46304.564 | E12: DAMAGE - Tamper Detected | F12: E285 WWA Payment Device (WiFi,512MB) | G12: M087-500-14-WWA | H12: 807-280-135 | K12: Mata Hann | L12: Advanced Exchange | Q12: Tessa | R12: Kopcha | S12: Dutch Bros #CA0903 | T12: Dutch Bros #CA0903
A13: 15767656 | B13: Pending Return | C13: 46304.557 | E13: DAMAGE - Tamper Detected | F13: E285 WWA Payment Device (WiFi,512MB) | G13: M087-500-14-WWA | H13: 807-068-963 | K13: Mata Hann | L13: Advanced Exchange | Q13: Andrew | R13: Randall | S13: Dutch Bros ID0604 | T13: Dutch Bros ID0604
A14: 15765796 | B14: Pending Return | C14: 46304.358 | E14: DAMAGE - Tamper Detected | F14: E285 WWA Payment Device (WiFi,512MB) | G14: M087-500-14-WWA | H14: 807-614-263 | K14: Mata Hann | L14: Advanced Exchange | Q14: Jose | R14: Gonzalez | S14: Dutch Bros CA4306 | T14: Dutch Bros CA4306
A15: 15765412 | B15: Pending Return | C15: 46304.333 | E15: DAMAGE - Tamper Detected | F15: E285 WWA Payment Device (WiFi,512MB) | G15: M087-500-14-WWA | H15: 807-210-229 | K15: Mata Hann | L15: Advanced Exchange | Q15: Michelle | R15: Fairey | S15: Dutch Bros CA1702 | T15: Dutch Bros CA1702
A16: 15765398 | B16: Pending Return | C16: 46304.327 | E16: HARD - Battery Problem | F16: E285 WWA Payment Device (WiFi,512MB) | G16: M087-500-14-WWA | H16: 807-217-459 | K16: Mata Hann | L16: Advanced Exchange | Q16: Nate | R16: Frary | S16: Dutch Bros CO0806 | T16: Dutch Bros CO0806
A17: 15765396 | C17: 46304.319 | E17: MISC - Lost/Stolen Device | F17: E285 WWA Payment Device (WiFi,512MB) | G17: M087-500-14-WWA | H17: 807-017-585 | K17: Mata Hann | L17: Unit Replacement | Q17: Clayton | R17: Reinhart | S17: Dutch Bros OR2506 | T17: Dutch Bros OR2506
A18: 15765394 | C18: 46304.317 | E18: MISC - Lost/Stolen Device | F18: E285 WWA Payment Device (WiFi,512MB) | G18: M087-500-14-WWA | H18: 807-356-174 | K18: Mata Hann | L18: Unit Replacement | Q18: Clayton | R18: Reinhart | S18: Dutch Bros OR2506 | T18: Dutch Bros OR2506
A19: 15765392 | C19: 46304.315 | E19: MISC - Lost/Stolen Device | F19: E285 WWA Payment Device (WiFi,512MB) | G19: M087-500-14-WWA | H19: 807-363-701 | K19: Mata Hann | L19: Unit Replacement | Q19: Clayton | R19: Reinhart | S19: Dutch Bros OR2506 | T19: Dutch Bros OR2506
A20: 15765214 | C20: 46304.311 | E20: MISC - Lost/Stolen Device | F20: E285 WWA Payment Device (WiFi,512MB) | G20: M087-500-14-WWA | H20: 807-256-065 | K20: Mata Hann | L20: Unit Replacement | Q20: Clayton | R20: Reinhart | S20: Dutch Bros OR2506 | T20: Dutch Bros OR2506
A21: 15765208 | C21: 46304.308 | E21: MISC - Lost/Stolen Device | F21: E285 WWA Payment Device (WiFi,512MB) | G21: M087-500-14-WWA | H21: 807-233-567 | K21: Mata Hann | L21: Unit Replacement | Q21: Clayton | R21: Reinhart | S21: Dutch Bros OR2506 | T21: Dutch Bros OR2506
A22: 15765202 | C22: 46304.303 | E22: MISC - Lost/Stolen Device | F22: E285 WWA Payment Device (WiFi,512MB) | G22: M087-500-14-WWA | H22: 807-244-783 | K22: Mata Hann | L22: Unit Replacement | Q22: Clayton | R22: Reinhart | S22: Dutch Bros OR2506 | T22: Dutch Bros OR2506
A23: 15761010 | B23: Pending Return | C23: 46303.694 | E23: MISC - Found Lost Device | F23: E285 WWA Payment Device (WiFi,512MB) | G23: M087-500-14-WWA | H23: 807-050-245 | K23: Sandra McNeill | L23: Eval and Return to Cust Stock | S23: Dutch Bros WA0304
A24: 15761006 | B24: Pending Return | C24: 46303.694 | E24: MISC - Found Lost Device | F24: E285 WWA Payment Device (WiFi,512MB) | G24: M087-500-14-WWA | H24: 807-198-019 | K24: Sandra McNeill | L24: Eval and Return to Cust Stock | S24: Dutch Bros WA0304
A25: 15760580 | B25: Pending Return | C25: 46303.651 | E25: DAMAGE - Physical Damage to Housing | F25: E285 WWA Payment Device (WiFi,512MB) | G25: M087-500-14-WWA | H25: 807-280-703 | K25: Mata Hann | L25: Advanced Exchange | Q25: Emmily | R25: Kirkpatrick | S25: Dutch Bros WA0405 | T25: Dutch Bros WA0405
A26: 15760198 | B26: Pending Return | C26: 46303.65 | E26: DAMAGE - Physical Damage to Housing | F26: E285 WWA Payment Device (WiFi,512MB) | G26: M087-500-14-WWA | H26: 807-078-743 | K26: Mata Hann | L26: Advanced Exchange | Q26: Emmily | R26: Kirkpatrick | S26: Dutch Bros WA0405 | T26: Dutch Bros WA0405
A27: 15760052 | C27: 46303.647 | E27: MISC - Lost/Stolen Device | F27: E285 WWA Payment Device (WiFi,512MB) | G27: M087-500-14-WWA | H27: 807-514-838 | K27: Mata Hann | L27: Unit Replacement | Q27: Emmily | R27: Kirkpatrick | S27: Dutch Bros WA0405 | T27: Dutch Bros WA0405
A28: 15760010 | B28: Pending Return | C28: 46303.632 | E28: HARD - Battery Problem | F28: E285 WWA Payment Device (WiFi,512MB) | G28: M087-500-14-WWA | H28: 807-245-450 | K28: Mata Hann | L28: Advanced Exchange | Q28: Jennifer | R28: Roberts | S28: Dutch Bros OR2601 | T28: Dutch Bros OR2601
A29: 15760004 | B29: Pending Return | C29: 46303.63 | E29: DAMAGE - Tamper Detected | F29: E285 WWA Payment Device (WiFi,512MB) | G29: M087-500-14-WWA | H29: 811-345-596 | K29: Mata Hann | L29: Advanced Exchange | Q29: Jennifer | R29: Roberts | S29: Dutch Bros OR2601 | T29: Dutch Bros OR2601
A30: 15759848 | B30: Pending Return | C30: 46303.622 | E30: HARD - Power Problem | F30: E285 WWA Payment Device (WiFi,512MB) | G30: M087-500-14-WWA | H30: 807-370-474 | K30: Mata Hann | L30: Advanced Exchange | Q30: Christina | R30: Gonzales | S30: Dutch Bros CA0701 | T30: Dutch Bros CA0701
A31: 15759406 | B31: Pending Return | C31: 46303.571 | E31: HARD - Power Problem | F31: E285 WWA Payment Device (WiFi,512MB) | G31: M087-500-14-WWA | H31: 807-657-615 | K31: Mata Hann | L31: Advanced Exchange | Q31: Blake | R31: Pratt | S31: Dutch Bros UT0101 | T31: Dutch Bros UT0101
A32: 15759326 | B32: Pending Return | C32: 46303.559 | E32: HARD - Battery Problem | F32: E285 WWA Payment Device (WiFi,512MB) | G32: M087-500-14-WWA | H32: 807-205-566 | K32: Mata Hann | L32: Advanced Exchange | Q32: Joni | R32: Castillo | S32: Dutch Bros TX3003 | T32: Dutch Bros TX3003
A33: 15759268 | B33: Pending Return | C33: 46303.55 | E33: DAMAGE - Tamper Detected | F33: E285 WWA Payment Device (WiFi,512MB) | G33: M087-500-14-WWA | H33: 807-226-153 | K33: Mata Hann | L33: Advanced Exchange | Q33: Josh | R33: Kimzey | S33: Dutch Bros OR3402 | T33: Dutch Bros OR3402
A34: 15758664 | B34: Pending Return | C34: 46303.497 | E34: DAMAGE - Tamper Detected | F34: E285 WWA Payment Device (WiFi,512MB) | G34: M087-500-14-WWA | H34: 807-210-184 | K34: Mata Hann | L34: Advanced Exchange | Q34: Lindsey | R34: Bianco | S34: Dutch Bros NM0401 | T34: Dutch Bros NM0401
A35: 15758650 | B35: Due Back | C35: 46303.493 | E35: DAMAGE - Tamper Detected | F35: E285 WWA Payment Device (WiFi,512MB) | G35: M087-500-14-WWA | H35: 807-188-738 | J35: 1Z1882X38792895175 | K35: Mata Hann | L35: Advanced Exchange | O35: 46304.877 | P35: 1Z1882X30296246241 | Q35: Brian | R35: Wight | S35: Dutch Bros ID0706 | T35: Dutch Bros ID0706
A36: 15758620 | B36: Due Back | C36: 46303.487 | E36: DAMAGE - Tamper Detected | F36: E285 WWA Payment Device (WiFi,512MB) | G36: M087-500-14-WWA | H36: 807-233-218 | J36: 1Z1882X38796084981 | K36: Mata Hann | L36: Advanced Exchange | O36: 46304.876 | P36: 1Z1882X30296073179 | Q36: Brian | R36: Wight | S36: Dutch Bros ID0706 | T36: Dutch Bros ID0706
A37: 15758468 | B37: Pending Return | C37: 46303.476 | E37: HARD - Power Problem | F37: E285 WWA Payment Device (WiFi,512MB) | G37: M087-500-14-WWA | H37: 807-395-150 | K37: Mata Hann | L37: Advanced Exchange | Q37: Nate | R37: Garvin | S37: Dutch Bros AL0103 | T37: Dutch Bros AL0103
A38: 15758424 | B38: Pending Return | C38: 46303.47 | E38: DAMAGE - Charging Port Damaged | F38: E285 WWA Payment Device (WiFi,512MB) | G38: M087-500-14-WWA | H38: 807-210-194 | K38: Mata Hann | L38: Advanced Exchange | Q38: Nate | R38: Garvin | S38: Dutch Bros AL0103 | T38: Dutch Bros AL0103
A39: 15758282 | B39: Pending Return | C39: 46303.455 | E39: DAMAGE - Charging Port Damaged | F39: E285 WWA Payment Device (WiFi,512MB) | G39: M087-500-14-WWA | H39: 807-280-592 | K39: Mata Hann | L39: Advanced Exchange | Q39: Abe | R39: Menshenfriend | S39: Dutch Bros OR2202 | T39: Dutch Bros OR2202
A40: 15758238 | B40: Pending Return | C40: 46303.447 | E40: DAMAGE - Physical Damage to Housing | F40: E285 WWA Payment Device (WiFi,512MB) | G40: M087-500-14-WWA | H40: 807-244-625 | K40: Mata Hann | L40: Advanced Exchange | Q40: Kevin | R40: Murphy | S40: Dutch Bros OR2304 | T40: Dutch Bros OR2304
...

Sheet 4. ir_LCM_2024- old
A1: Month | B1: Install Base Verifone | C1: Actual RMAs Verifone | D1: Contractual IR 5% | E1: Verifone
A2: Jan | B2: 10081 | C2: 602 | D2: 0.01 | E2: =C2/B2 -> 0.059716298
A3: Feb | B3: 10081 | C3: 472 | D3: 0.01 | E3: =C3/B3 -> 0.046820752
A4: Mar | B4: 10174 | C4: 547 | D4: 0.01 | E4: =C4/B4 -> 0.053764498
A5: Apr | B5: 10142 | C5: 546 | D5: 0.01 | E5: =C5/B5 -> 0.053835535
A6: May | B6: 10428 | C6: 519 | D6: 0.01 | E6: =C6/B6 -> 0.04976985
A7: Jun | B7: 10575 | C7: 572 | D7: 0.01 | E7: =C7/B7 -> 0.054089835
A8: Jul (old rate) | B8: =Overages!C52 -> 10773 | C8: =Overages!B52 -> 329 | D8: 0.01 | E8: =C8/B8 -> 0.030539311
A9: Jul (new rate) | B9: =Overages!C53 -> 10773 | C9: =Overages!B53 -> 326 | D9: 0.05 | E9: =C9/B9 -> 0.030260837
A10: Aug | B10: =Overages!C54 -> 11086 | C10: =Overages!B54 -> 554 | D10: 0.05 | E10: =C10/B10 -> 0.049972939
A11: Sep | B11: =Overages!C55 -> 11179 | C11: =Overages!B55 -> 523 | D11: 0.05 | E11: =C11/B11 -> 0.046784149
A12: Oct | B12: =Overages!C56 -> 11304 | C12: =Overages!B56 -> 551 | D12: 0.05 | E12: =C12/B12 -> 0.048743808
A13: Nov | B13: =Overages!C57 -> 11343 | C13: =Overages!B57 -> 499 | D13: 0.05 | E13: =C13/B13 -> 0.043991889
A14: Dec | B14: =Overages!C58 -> 11447 | C14: =Overages!B58 -> 612 | D14: 0.05 | E14: =C14/B14 -> 0.05346379
A15: Total | C15: =SUM(C2:C14) -> 6652 | E15: =AVERAGE(E2:E14) -> 0.047827192
